2025-05-13 13:38:22,649 - INFO - 使用GPU: NVIDIA GeForce GTX 1650
2025-05-13 13:38:22,649 - INFO - CUDA版本: 12.8
2025-05-13 13:38:22,649 - INFO - 正在加载Phi-1.5模型...
2025-05-13 13:38:42,706 - ERROR - 模型加载失败: We couldn't connect to 'https://huggingface.co' to load the files, and couldn't find them in the cached files.
Checkout your internet connection or see how to run the library in offline mode at 'https://huggingface.co/docs/transformers/installation#offline-mode'.
Traceback (most recent call last):
  File "D:\bs\PEPPER_AI_Classroom\venv_ai\lib\site-packages\urllib3\connection.py", line 198, in _new_conn
    sock = connection.create_connection(
  File "D:\bs\PEPPER_AI_Classroom\venv_ai\lib\site-packages\urllib3\util\connection.py", line 85, in create_connection
    raise err
  File "D:\bs\PEPPER_AI_Classroom\venv_ai\lib\site-packages\urllib3\util\connection.py", line 73, in create_connection
    sock.connect(sa)
TimeoutError: timed out

The above exception was the direct cause of the following exception:

Traceback (most recent call last):
  File "D:\bs\PEPPER_AI_Classroom\venv_ai\lib\site-packages\urllib3\connectionpool.py", line 787, in urlopen
    response = self._make_request(
  File "D:\bs\PEPPER_AI_Classroom\venv_ai\lib\site-packages\urllib3\connectionpool.py", line 488, in _make_request
    raise new_e
  File "D:\bs\PEPPER_AI_Classroom\venv_ai\lib\site-packages\urllib3\connectionpool.py", line 464, in _make_request
    self._validate_conn(conn)
  File "D:\bs\PEPPER_AI_Classroom\venv_ai\lib\site-packages\urllib3\connectionpool.py", line 1093, in _validate_conn
    conn.connect()
  File "D:\bs\PEPPER_AI_Classroom\venv_ai\lib\site-packages\urllib3\connection.py", line 704, in connect
    self.sock = sock = self._new_conn()
  File "D:\bs\PEPPER_AI_Classroom\venv_ai\lib\site-packages\urllib3\connection.py", line 207, in _new_conn
    raise ConnectTimeoutError(
urllib3.exceptions.ConnectTimeoutError: (<urllib3.connection.HTTPSConnection object at 0x000002167B14C430>, 'Connection to huggingface.co timed out. (connect timeout=10)')

The above exception was the direct cause of the following exception:

Traceback (most recent call last):
  File "D:\bs\PEPPER_AI_Classroom\venv_ai\lib\site-packages\requests\adapters.py", line 667, in send
    resp = conn.urlopen(
  File "D:\bs\PEPPER_AI_Classroom\venv_ai\lib\site-packages\urllib3\connectionpool.py", line 841, in urlopen
    retries = retries.increment(
  File "D:\bs\PEPPER_AI_Classroom\venv_ai\lib\site-packages\urllib3\util\retry.py", line 519, in increment
    raise MaxRetryError(_pool, url, reason) from reason  # type: ignore[arg-type]
urllib3.exceptions.MaxRetryError: HTTPSConnectionPool(host='huggingface.co', port=443): Max retries exceeded with url: /microsoft/phi-1_5/resolve/main/config.json (Caused by ConnectTimeoutError(<urllib3.connection.HTTPSConnection object at 0x000002167B14C430>, 'Connection to huggingface.co timed out. (connect timeout=10)'))

During handling of the above exception, another exception occurred:

Traceback (most recent call last):
  File "D:\bs\PEPPER_AI_Classroom\venv_ai\lib\site-packages\huggingface_hub\file_download.py", line 1531, in _get_metadata_or_catch_error
    metadata = get_hf_file_metadata(
  File "D:\bs\PEPPER_AI_Classroom\venv_ai\lib\site-packages\huggingface_hub\utils\_validators.py", line 114, in _inner_fn
    return fn(*args, **kwargs)
  File "D:\bs\PEPPER_AI_Classroom\venv_ai\lib\site-packages\huggingface_hub\file_download.py", line 1448, in get_hf_file_metadata
    r = _request_wrapper(
  File "D:\bs\PEPPER_AI_Classroom\venv_ai\lib\site-packages\huggingface_hub\file_download.py", line 286, in _request_wrapper
    response = _request_wrapper(
  File "D:\bs\PEPPER_AI_Classroom\venv_ai\lib\site-packages\huggingface_hub\file_download.py", line 309, in _request_wrapper
    response = http_backoff(method=method, url=url, **params, retry_on_exceptions=(), retry_on_status_codes=(429,))
  File "D:\bs\PEPPER_AI_Classroom\venv_ai\lib\site-packages\huggingface_hub\utils\_http.py", line 310, in http_backoff
    response = session.request(method=method, url=url, **kwargs)
  File "D:\bs\PEPPER_AI_Classroom\venv_ai\lib\site-packages\requests\sessions.py", line 589, in request
    resp = self.send(prep, **send_kwargs)
  File "D:\bs\PEPPER_AI_Classroom\venv_ai\lib\site-packages\requests\sessions.py", line 703, in send
    r = adapter.send(request, **kwargs)
  File "D:\bs\PEPPER_AI_Classroom\venv_ai\lib\site-packages\huggingface_hub\utils\_http.py", line 96, in send
    return super().send(request, *args, **kwargs)
  File "D:\bs\PEPPER_AI_Classroom\venv_ai\lib\site-packages\requests\adapters.py", line 688, in send
    raise ConnectTimeout(e, request=request)
requests.exceptions.ConnectTimeout: (MaxRetryError("HTTPSConnectionPool(host='huggingface.co', port=443): Max retries exceeded with url: /microsoft/phi-1_5/resolve/main/config.json (Caused by ConnectTimeoutError(<urllib3.connection.HTTPSConnection object at 0x000002167B14C430>, 'Connection to huggingface.co timed out. (connect timeout=10)'))"), '(Request ID: 843bb442-009a-4391-ae26-df532b5be030)')

The above exception was the direct cause of the following exception:

Traceback (most recent call last):
  File "D:\bs\PEPPER_AI_Classroom\venv_ai\lib\site-packages\transformers\utils\hub.py", line 424, in cached_files
    hf_hub_download(
  File "D:\bs\PEPPER_AI_Classroom\venv_ai\lib\site-packages\huggingface_hub\utils\_validators.py", line 114, in _inner_fn
    return fn(*args, **kwargs)
  File "D:\bs\PEPPER_AI_Classroom\venv_ai\lib\site-packages\huggingface_hub\file_download.py", line 1008, in hf_hub_download
    return _hf_hub_download_to_cache_dir(
  File "D:\bs\PEPPER_AI_Classroom\venv_ai\lib\site-packages\huggingface_hub\file_download.py", line 1115, in _hf_hub_download_to_cache_dir
    _raise_on_head_call_error(head_call_error, force_download, local_files_only)
  File "D:\bs\PEPPER_AI_Classroom\venv_ai\lib\site-packages\huggingface_hub\file_download.py", line 1646, in _raise_on_head_call_error
    raise LocalEntryNotFoundError(
huggingface_hub.errors.LocalEntryNotFoundError: An error happened while trying to locate the file on the Hub and we cannot find the requested files in the local cache. Please check your connection and try again or make sure your Internet connection is on.

The above exception was the direct cause of the following exception:

Traceback (most recent call last):
  File "D:\bs\PEPPER_AI_Classroom\fix_gpu_response.py", line 134, in load_model
    tokenizer = AutoTokenizer.from_pretrained(model_name)
  File "D:\bs\PEPPER_AI_Classroom\venv_ai\lib\site-packages\transformers\models\auto\tokenization_auto.py", line 966, in from_pretrained
    config = AutoConfig.from_pretrained(
  File "D:\bs\PEPPER_AI_Classroom\venv_ai\lib\site-packages\transformers\models\auto\configuration_auto.py", line 1114, in from_pretrained
    config_dict, unused_kwargs = PretrainedConfig.get_config_dict(pretrained_model_name_or_path, **kwargs)
  File "D:\bs\PEPPER_AI_Classroom\venv_ai\lib\site-packages\transformers\configuration_utils.py", line 590, in get_config_dict
    config_dict, kwargs = cls._get_config_dict(pretrained_model_name_or_path, **kwargs)
  File "D:\bs\PEPPER_AI_Classroom\venv_ai\lib\site-packages\transformers\configuration_utils.py", line 649, in _get_config_dict
    resolved_config_file = cached_file(
  File "D:\bs\PEPPER_AI_Classroom\venv_ai\lib\site-packages\transformers\utils\hub.py", line 266, in cached_file
    file = cached_files(path_or_repo_id=path_or_repo_id, filenames=[filename], **kwargs)
  File "D:\bs\PEPPER_AI_Classroom\venv_ai\lib\site-packages\transformers\utils\hub.py", line 491, in cached_files
    raise OSError(
OSError: We couldn't connect to 'https://huggingface.co' to load the files, and couldn't find them in the cached files.
Checkout your internet connection or see how to run the library in offline mode at 'https://huggingface.co/docs/transformers/installation#offline-mode'.
2025-05-13 13:38:42,733 - ERROR - 模型加载失败，无法启动API服务
